---
layout: post
title: "[python] Handling failures and retries in Python Celery"
description: " "
date: 2023-10-11
tags: [python]
comments: true
share: true
---

In distributed systems, failures are inevitable. When using a task queue like Celery in Python, it is important to handle failures properly to ensure the reliability and correctness of your application. One common strategy for dealing with failures is to implement retries, which involves attempting to execute a failed task again after a certain period of time. In this article, we will explore how to handle failures and retries in Python Celery.

## The `retry` parameter

Celery provides a `retry` parameter that you can use to configure retries for a task. When a task encounters an exception, Celery will automatically retry the task based on the `retry` configuration.

Here's an example of a task that retries a maximum of 3 times with a 5-second delay between retries:

```python
from celery import Celery, Task

app = Celery('myapp', broker='redis://localhost:6379/0')

class MyTask(Task):
    max_retries = 3
    default_retry_delay = 5

    def run(self, *args, **kwargs):
        try:
            # Your task logic here
            pass
        except Exception as exc:
            # Retry the task
            raise self.retry(exc=exc)

app.tasks.register(MyTask)
```

In this example, if an exception occurs inside the task's `run` method, the task will be retried up to 3 times with a 5-second delay between retries. If the task still fails after exhausting all retries, it will be marked as failed.

## Customizing retry behavior

You can also customize the retry behavior by changing the values of `max_retries` and `default_retry_delay` attributes in your task class. 

For example, you can increase the maximum number of retries to 5 and delay each retry by 10 seconds:

```python
class MyTask(Task):
    max_retries = 5
    default_retry_delay = 10
```

You can even set `max_retries` to `None` to specify unlimited retries:

```python
class MyTask(Task):
    max_retries = None
    default_retry_delay = 5
```

## Handling specific exceptions

By default, Celery will retry the task for any exception. However, you can specify certain exceptions for which retries should be attempted. This can be done using the `retry` parameter with the `retry_on` argument.

Here's an example of a task that retries only when a `ValueError` occurs:

```python
class MyTask(Task):
    retry_on = (ValueError,)

    def run(self, *args, **kwargs):
        try:
            # Your task logic here
            pass
        except ValueError as exc:
            # Retry the task
            raise self.retry(exc=exc)
```

In this case, the task will only retry if a `ValueError` is raised. Any other exception will be considered a failure and will not trigger a retry.

## Exponential backoff

Another important aspect of handling failures and retries is implementing an exponential backoff strategy. Instead of retrying with a fixed delay, you can increase the delay exponentially with each retry. This can help reduce the load on your system and prevent overwhelming the resources.

Celery provides a built-in `retry_backoff` attribute that you can use to enable exponential backoff:

```python
class MyTask(Task):
    retry_backoff = True
    default_retry_delay = 5
```

With this configuration, the delay between retries will increase exponentially. Each retry will have a longer delay than the previous one.

## Conclusion

Handling failures and retries properly is crucial in building robust and reliable distributed systems. In Python Celery, you can configure retries using the `retry` parameter and customize the retry behavior based on your specific needs. By implementing retry strategies and utilizing features like exponential backoff, you can improve the reliability of your tasks and ensure graceful error handling in your application.

Remember, failures are inevitable, but how you handle them can make all the difference in the performance and success of your system.