---
layout: post
title: "[python] Handling errors in Prefect flows"
description: " "
date: 2023-10-18
tags: [python]
comments: true
share: true
---

Prefect is a powerful Python library for building, scheduling, and running data workflows. One crucial aspect of building robust workflows is handling errors that may occur during their execution. In this blog post, we will explore different techniques for handling errors in Prefect flows.

## Table of Contents
- [Error Handling in Prefect](#error-handling-in-prefect)
- [Using `try-except` Blocks](#using-try-except-blocks)
- [Raising Custom Exceptions](#raising-custom-exceptions)
- [Retrying Failed Tasks](#retrying-failed-tasks)
- [Handling Errors with `on_failure`](#handling-errors-with-on_failure)
- [Logging Error Messages](#logging-error-messages)
- [Conclusion](#conclusion)

## Error Handling in Prefect

Before diving into specific error handling techniques, let's first understand how Prefect handles errors by default. By default, Prefect will raise an exception and immediately stop the flow execution when a task fails. This behavior helps in quickly identifying issues during the development and testing phase. However, in production workflows, we might want more flexibility in handling errors.

## Using `try-except` Blocks

One straightforward way to handle errors in Prefect flows is by using `try-except` blocks. Inside a task's `run` method, you can wrap specific parts of the code that may raise exceptions with a `try` block and catch the corresponding exceptions in the `except` block. This allows you to perform custom error handling logic.

Here is an example:

```python
from prefect import task

@task
def divide_by_zero():
    try:
        result = 10 / 0
        return result
    except ZeroDivisionError:
        # Custom error handling logic
        return "Error: Division by zero occurred"
```

In the above example, if an exception of type `ZeroDivisionError` is raised during the division, the flow will not fail abruptly. Instead, the error will be caught, and the custom error message will be returned.

## Raising Custom Exceptions

In addition to handling built-in exceptions, Prefect allows you to define and raise your custom exceptions during flow execution. This can be useful for distinguishing between different types of errors and providing specific error messages or actions based on those errors.

Here is an example:

```python
from prefect import task, TaskFailed

@task
def validate_input(value):
    if isinstance(value, int):
        return value
    else:
        raise TaskFailed("Error: Invalid input type. Expected integer.")
```

In the above example, if the input value is not an integer, the `TaskFailed` exception will be raised, and the provided error message will be displayed. This helps in explicitly signaling the incorrect input type as the reason for the task failure.

## Retrying Failed Tasks

Prefect provides a built-in mechanism for retrying failed tasks. You can specify the desired number of retries and the delay between each retry.

Here is an example:

```python
from prefect import task

@task(max_retries=3, retry_delay=timedelta(minutes=1))
def download_data(url):
    try:
        # Code to download data
        return data
    except Exception as e:
        raise type(e)("Error: Failed to download data") from e
```

In the above example, if the task fails, Prefect will automatically retry it up to three times, with a one-minute delay between each retry. This helps in dealing with transient errors and network connectivity issues.

## Handling Errors with `on_failure`

Another way to handle errors in Prefect flows is by using the `on_failure` method provided by Prefect's `Flow` class. This method allows you to specify a callback function that will be executed when any task in the flow fails.

Here is an example:

```python
from prefect import Flow

def on_failure(task, old_state, *args, **kwargs):
    # Custom error handling logic
    print(f"Error occurred in task: {task.name}")
    print(f"Error state: {old_state}")

flow = Flow("My Flow")
flow.on_failure = on_failure
```

In the above example, the `on_failure` function will be called whenever any task in the flow fails. You can customize this function to perform actions like sending notifications, logging errors, or triggering retries.

## Logging Error Messages

Logging is an essential tool for error handling and debugging. Prefect provides methods for logging error messages or any other useful information during flow execution. You can use the `logger` object available inside task `run` methods to log messages.

Here is an example:

```python
from prefect import task, context

@task
def process_data(data):
    try:
        # Some data processing logic
        result = ...
        return result
    except Exception as e:
        logger = context.get("logger")
        logger.error(f"Error occurred: {str(e)}")
```

In the above example, whenever an exception occurs during data processing, the error message will be logged using the `logger.error` method. This helps in capturing and analyzing errors during runtime.

## Conclusion

Handling errors is a critical aspect of building robust data workflows using Prefect. In this blog post, we explored different techniques for handling errors, such as using `try-except` blocks, raising custom exceptions, retrying failed tasks, using `on_failure` callbacks, and logging error messages. By leveraging these techniques, you can make your Prefect flows more fault-tolerant and reliable.

Remember to always consider the specific requirements of your workflows and design error handling strategies accordingly.

References:
- [Prefect Documentation](https://docs.prefect.io/)
- [Python Exception Handling](https://docs.python.org/3/tutorial/errors.html)