---
layout: post
title: "[python] Exception handling in Python generators"
description: " "
date: 2023-10-18
tags: [python]
comments: true
share: true
---

Python generators are a powerful feature that allows you to iterate over a sequence of values lazily. They are defined using the `yield` keyword and can be used to create iterators in a concise and readable manner.

When working with generators, it is important to handle exceptions gracefully to maintain proper control flow and ensure that all resources are properly cleaned up. In this blog post, we will explore how to handle exceptions in Python generators.

## Understanding generator exceptions

Generator functions can raise exceptions like any other Python function. However, there are a few key differences to consider when dealing with exceptions in generators.

1. **GeneratorStop**: If a generator function raises a `GeneratorExit` exception or executes a `return` statement, it automatically raises a `GeneratorStop` exception. This is used to signal the end of iteration and is caught and swallowed by the interpreter.

2. **StopIteration**: When a generator function has no more values to yield, it raises a `StopIteration` exception. This is also caught and handled by the interpreter when using a `for` loop or the `next()` function.

## Handling exceptions in generators

To handle exceptions in generators, you can use a `try...except` block within the generator function.

```python
def my_generator():
    try:
        # Generator code here
        yield value
    except Exception as e:
        # Exception handling code here
        yield fallback_value
```

In the code above, we wrap our generator code in a `try` block and catch any exceptions using `except`. Inside the `except` block, we can handle the exception as needed and yield a fallback value instead of propagating the exception to the caller.

By doing this, we ensure that even if an exception occurs during the generation of values, the generator can continue providing values afterwards, if possible.

## Example: Handling division by zero

Let's consider an example where we have a generator that yields the result of dividing two numbers:

```python
def division_generator(numbers):
    for divisor in numbers:
        try:
            yield 100 / divisor
        except ZeroDivisionError:
            yield "Cannot divide by zero"
```

In this code, we are iterating over a sequence of divisors and calculating the result of dividing 100 by each of them. If a `ZeroDivisionError` occurs, we catch it and yield the string `"Cannot divide by zero"` instead.

## Conclusion

Exception handling is an important aspect of writing robust and reliable code, including when working with Python generators. By using a `try...except` block within a generator function, you can handle exceptions gracefully and ensure the generator continues to yield values, even in the presence of errors.

Proper exception handling in generators is crucial for maintaining control flow and avoiding unexpected termination. By understanding how exceptions behave in generators and using the appropriate handling mechanisms, you can write more robust and resilient code.

References:
- [Python Generators](https://docs.python.org/3/glossary.html#term-generator)
- [Python Exception Handling](https://docs.python.org/3/tutorial/errors.html)