---
layout: post
title: "[python] Exception handling with Asyncio"
description: " "
date: 2023-10-13
tags: [python]
comments: true
share: true
---

When working with asynchronous programming in Python using the `asyncio` library, it is essential to handle exceptions effectively. Exception handling in `asyncio` is slightly different from traditional synchronous programming, as the code is executed in a non-blocking manner. In this blog post, we will explore how to handle exceptions with `asyncio` and discuss some best practices.

## Error propagation in async functions

In `asyncio`, when an exception occurs inside an `async` function, it propagates up the call stack until it is caught. If the exception goes unhandled, it will result in a `RuntimeError` or a traceback being printed to the console.

```python
import asyncio

async def foo():
    raise ValueError("Something went wrong")

async def bar():
    await foo()

async def main():
    try:
        await bar()
    except ValueError as e:
        print(f"Caught exception: {e}")

asyncio.run(main())
```

In the example above, the `foo` function raises a `ValueError`, which is then caught in the `main` function using a conventional `try-except` block.

## Handling exceptions in coroutines

`asyncio` provides a mechanism to handle exceptions within coroutines using the `try-except` block. Inside an `async` function, you can use a `try` block to catch and handle exceptions.

```python
import asyncio

async def foo():
    try:
        raise ValueError("Something went wrong")
    except ValueError as e:
        print(f"Caught exception inside coroutine: {e}")

async def main():
    await foo()

asyncio.run(main())
```

In this example, the exception is caught inside the `foo` function itself. This allows you to handle the exception without propagating it further up the call stack.

## Exception handling in tasks and futures

When working with `asyncio` tasks and futures, you can handle exceptions using the `add_done_callback` method. This method adds a callback function to a future object that will be called when the future is done, with the future object as the argument.

```python
import asyncio

async def foo():
    raise ValueError("Something went wrong")

async def main():
    fut = asyncio.ensure_future(foo())
    fut.add_done_callback(lambda f: print(f"Caught exception in future: {f.exception()}"))

asyncio.run(main())
```

In this example, we create a future from the `foo` coroutine using `asyncio.ensure_future`. We then add a callback function using `add_done_callback`, which will print the exception if it occurs.

## Conclusion

Exception handling in `asyncio` follows similar patterns to synchronous programming, with some minor differences. By using `try-except` blocks within coroutines or attaching callback functions to futures, you can effectively handle exceptions in your `asyncio` code, ensuring robust error handling in asynchronous applications.

References:
- [Python Docs - asyncio](https://docs.python.org/3/library/asyncio.html)
- [Real Python - Async IO in Python: A Complete Walkthrough](https://realpython.com/async-io-python/)
- [Stack Overflow - Exception handling with asyncio](https://stackoverflow.com/questions/47749638/correct-way-to-handle-exceptions-within-an-asyncio-event-loop)